<?xml version="1.0"?>
<robot name="simple_robot">
  <!-- Base link -->
  <link name="base_link">
    <visual>
      <geometry>
        <cylinder radius="0.2" length="0.1"/>
      </geometry>
      <material name="blue">
        <color rgba="0 0 0.8 1"/>
      </material>
    </visual>
    <collision>
      <geometry>
        <cylinder radius="0.2" length="0.1"/>
      </geometry>
    </collision>
    <inertial>
      <mass value="1"/>
      <inertia ixx="0.1" ixy="0" ixz="0" iyy="0.1" iyz="0" izz="0.1"/>
    </inertial>
  </link>

  <!-- Wheel links -->
  <link name="wheel_front_left">
    <visual>
      <geometry>
        <cylinder radius="0.1" length="0.05"/>
      </geometry>
      <material name="black">
        <color rgba="0 0 0 1"/>
      </material>
    </visual>
  </link>

  <link name="wheel_front_right">
    <visual>
      <geometry>
        <cylinder radius="0.1" length="0.05"/>
      </geometry>
      <material name="black">
        <color rgba="0 0 0 1"/>
      </material>
    </visual>
  </link>

  <!-- Joints -->
  <joint name="front_left_wheel_joint" type="continuous">
    <parent link="base_link"/>
    <child link="wheel_front_left"/>
    <origin xyz="0.1 0.15 0" rpy="0 0 0"/>
    <axis xyz="0 1 0"/>
  </joint>

  <joint name="front_right_wheel_joint" type="continuous">
    <parent link="base_link"/>
    <child link="wheel_front_right"/>
    <origin xyz="0.1 -0.15 0" rpy="0 0 0"/>
    <axis xyz="0 1 0"/>
  </joint>
</robot>